<sdf version='1.7'>
  <world name='default'>
    <light name='sun' type='directional'>
      <cast_shadows>1</cast_shadows>
      <pose>0 0 10 0 -0 0</pose>
      <diffuse>0.8 0.8 0.8 1</diffuse>
      <specular>0.2 0.2 0.2 1</specular>
      <attenuation>
        <range>1000</range>
        <constant>0.9</constant>
        <linear>0.01</linear>
        <quadratic>0.001</quadratic>
      </attenuation>
      <direction>-0.5 0.1 -0.9</direction>
      <spot>
        <inner_angle>0</inner_angle>
        <outer_angle>0</outer_angle>
        <falloff>0</falloff>
      </spot>
    </light>
    <model name='ground_plane'>
      <static>1</static>
      <link name='link'>
        <collision name='collision'>
          <geometry>
            <plane>
              <normal>0 0 1</normal>
              <size>100 100</size>
            </plane>
          </geometry>
          <surface>
            <friction>
              <ode>
                <mu>100</mu>
                <mu2>50</mu2>
              </ode>
              <torsional>
                <ode/>
              </torsional>
            </friction>
            <contact>
              <ode/>
            </contact>
            <bounce/>
          </surface>
          <max_contacts>10</max_contacts>
        </collision>
        <visual name='visual'>
          <cast_shadows>0</cast_shadows>
          <geometry>
            <plane>
              <normal>0 0 1</normal>
              <size>100 100</size>
            </plane>
          </geometry>
          <material>
            <script>
              <uri>file://media/materials/scripts/gazebo.material</uri>
              <name>Gazebo/Grey</name>
            </script>
          </material>
        </visual>
        <self_collide>0</self_collide>
        <enable_wind>0</enable_wind>
        <kinematic>0</kinematic>
      </link>
    </model>
    <gravity>0 0 -9.8</gravity>
    <magnetic_field>6e-06 2.3e-05 -4.2e-05</magnetic_field>
    <atmosphere type='adiabatic'/>
    <physics type='ode'>
      <max_step_size>0.001</max_step_size>
      <real_time_factor>1</real_time_factor>
      <real_time_update_rate>1000</real_time_update_rate>
    </physics>
    <scene>
      <ambient>0.4 0.4 0.4 1</ambient>
      <background>0.7 0.7 0.7 1</background>
      <shadows>1</shadows>
    </scene>
    <audio>
      <device>default</device>
    </audio>
    <wind/>
    <spherical_coordinates>
      <surface_model>EARTH_WGS84</surface_model>
      <latitude_deg>0</latitude_deg>
      <longitude_deg>0</longitude_deg>
      <elevation>0</elevation>
      <heading_deg>0</heading_deg>
    </spherical_coordinates>
    <model name='limo_description'>
      <link name='base_footprint'>
        <inertial>
          <pose>0.007905 0 0.160821 0 -0 0</pose>
          <mass>2.3657</mass>
          <inertia>
            <ixx>0.248941</ixx>
            <ixy>0</ixy>
            <ixz>-0.00196744</ixz>
            <iyy>0.970559</iyy>
            <iyz>0</iyz>
            <izz>0.961621</izz>
          </inertia>
        </inertial>
        <collision name='base_footprint_fixed_joint_lump__base_link_collision'>
          <pose>0 0 0.15 0 -0 0</pose>
          <geometry>
            <box>
              <size>0.13 0.12 0.1</size>
            </box>
          </geometry>
          <max_contacts>10</max_contacts>
          <surface>
            <contact>
              <ode/>
            </contact>
            <bounce/>
            <friction>
              <torsional>
                <ode/>
              </torsional>
              <ode/>
            </friction>
          </surface>
        </collision>
        <collision name='base_footprint_fixed_joint_lump__depth_camera_collision_collision_1'>
          <pose>0.084 0 0.45 0 -0 0</pose>
          <geometry>
            <box>
              <size>0.02 0.06 0.015</size>
            </box>
          </geometry>
          <max_contacts>10</max_contacts>
          <surface>
            <contact>
              <ode/>
            </contact>
            <bounce/>
            <friction>
              <torsional>
                <ode/>
              </torsional>
              <ode/>
            </friction>
          </surface>
        </collision>
        <collision name='base_footprint_fixed_joint_lump__imu_collision_collision_2'>
          <pose>0 0 0.05 0 -0 0</pose>
          <geometry>
            <box>
              <size>0.001 0.001 0.001</size>
            </box>
          </geometry>
          <max_contacts>10</max_contacts>
          <surface>
            <contact>
              <ode/>
            </contact>
            <bounce/>
            <friction>
              <torsional>
                <ode/>
              </torsional>
              <ode/>
            </friction>
          </surface>
        </collision>
        <collision name='base_footprint_fixed_joint_lump__laser_collision_collision_3'>
          <pose>0.103 0 0.116 0 -0 0</pose>
          <geometry>
            <cylinder>
              <length>0.016</length>
              <radius>0.032</radius>
            </cylinder>
          </geometry>
          <max_contacts>10</max_contacts>
          <surface>
            <contact>
              <ode/>
            </contact>
            <bounce/>
            <friction>
              <torsional>
                <ode/>
              </torsional>
              <ode/>
            </friction>
          </surface>
        </collision>
        <visual name='base_footprint_fixed_joint_lump__base_link_visual'>
          <pose>0 0 0 0 -0 1.57</pose>
          <geometry>
            <mesh>
              <scale>1 1 1</scale>
              <uri>file:///home/agilex/agilex_ws/install/limo_description/share/limo_description/meshes/limo_base.dae</uri>
            </mesh>
          </geometry>
        </visual>
        <visual name='base_footprint_fixed_joint_lump__depth_camera_visual_visual_1'>
          <pose>0.084 0 0.45 0 -0 0</pose>
          <geometry>
            <box>
              <size>0.02 0.06 0.015</size>
            </box>
          </geometry>
        </visual>
        <visual name='base_footprint_fixed_joint_lump__imu_visual_visual_2'>
          <pose>0 0 0.05 0 -0 0</pose>
          <geometry>
            <box>
              <size>0.001 0.001 0.001</size>
            </box>
          </geometry>
        </visual>
        <visual name='base_footprint_fixed_joint_lump__laser_visual_visual_3'>
          <pose>0.103 0 0.116 0 -0 0</pose>
          <geometry>
            <cylinder>
              <length>0.01</length>
              <radius>0.02</radius>
            </cylinder>
          </geometry>
        </visual>
        <gravity>1</gravity>
        <sensor name='twr_imu' type='imu'>
          <always_on>1</always_on>
          <update_rate>100</update_rate>
          <visualize>1</visualize>
          <imu>
            <angular_velocity>
              <x>
                <noise type='gaussian'>
                  <mean>0</mean>
                  <stddev>0.0002</stddev>
                </noise>
              </x>
              <y>
                <noise type='gaussian'>
                  <mean>0</mean>
                  <stddev>0.0002</stddev>
                </noise>
              </y>
              <z>
                <noise type='gaussian'>
                  <mean>0</mean>
                  <stddev>0.0002</stddev>
                </noise>
              </z>
            </angular_velocity>
            <linear_acceleration>
              <x>
                <noise type='gaussian'>
                  <mean>0</mean>
                  <stddev>0.017</stddev>
                </noise>
              </x>
              <y>
                <noise type='gaussian'>
                  <mean>0</mean>
                  <stddev>0.017</stddev>
                </noise>
              </y>
              <z>
                <noise type='gaussian'>
                  <mean>0</mean>
                  <stddev>0.017</stddev>
                </noise>
              </z>
            </linear_acceleration>
            <orientation>
              <x>
                <noise type='gaussian'>
                  <mean>0.0</mean>
                  <stddev>2e-3</stddev>
                </noise>
              </x>
              <y>
                <noise type='gaussian'>
                  <mean>0.0</mean>
                  <stddev>2e-3</stddev>
                </noise>
              </y>
              <z>
                <noise type='gaussian'>
                  <mean>0.0</mean>
                  <stddev>2e-3</stddev>
                </noise>
              </z>
            </orientation>
          </imu>
          <plugin name='two_wheeled_robot_imu' filename='libgazebo_ros_imu_sensor.so'>
            <initial_orientation_as_reference>0</initial_orientation_as_reference>
            <frame_name>imu_link</frame_name>
            <ros>
              <namespace>/imu</namespace>
              <remapping>~/out:=data</remapping>
            </ros>
          </plugin>
          <pose>0 0 0.05 0 -0 0</pose>
        </sensor>
        <sensor name='laser' type='ray'>
          <always_on>1</always_on>
          <visualize>1</visualize>
          <update_rate>10</update_rate>
          <ray>
            <scan>
              <horizontal>
                <samples>120</samples>
                <resolution>1</resolution>
                <min_angle>-3.14159</min_angle>
                <max_angle>3.14159</max_angle>
              </horizontal>
              <vertical>
                <samples>1</samples>
                <min_angle>0</min_angle>
                <max_angle>0</max_angle>
              </vertical>
            </scan>
            <range>
              <min>0.3</min>
              <max>15</max>
              <resolution>0.015</resolution>
            </range>
            <noise>
              <type>gaussian</type>
              <mean>0</mean>
              <stddev>0.01</stddev>
            </noise>
          </ray>
          <plugin name='scan' filename='libgazebo_ros_ray_sensor.so'>
            <ros>
              <remapping>~/out:=scan</remapping>
            </ros>
            <output_type>sensor_msgs/LaserScan</output_type>
            <frame_name>laser_link</frame_name>
          </plugin>
          <pose>0.103 0 0.116 0 -0 0</pose>
        </sensor>
        <self_collide>0</self_collide>
        <enable_wind>0</enable_wind>
        <kinematic>0</kinematic>
      </link>
      <joint name='front_left_wheel' type='revolute'>
        <pose relative_to='base_footprint'>0.1 0.065 0.05 0 -0 0</pose>
        <parent>base_footprint</parent>
        <child>front_left_wheel_link</child>
        <axis>
          <xyz>0 1 0</xyz>
          <limit>
            <lower>-1e+16</lower>
            <upper>1e+16</upper>
          </limit>
          <dynamics>
            <spring_reference>0</spring_reference>
            <spring_stiffness>0</spring_stiffness>
          </dynamics>
        </axis>
        <physics>
          <ode>
            <limit>
              <cfm>0</cfm>
              <erp>0.2</erp>
            </limit>
          </ode>
        </physics>
      </joint>
      <link name='front_left_wheel_link'>
        <pose relative_to='front_left_wheel'>0 0 0 0 -0 0</pose>
        <inertial>
          <pose>0 0 0 0 -0 0</pose>
          <mass>0.5</mass>
          <inertia>
            <ixx>0.01055</ixx>
            <ixy>0</ixy>
            <ixz>0</ixz>
            <iyy>0.00075</iyy>
            <iyz>0</iyz>
            <izz>0.01055</izz>
          </inertia>
        </inertial>
        <collision name='front_left_wheel_link_collision'>
          <pose>0 0.0225 0 1.57 -0 0</pose>
          <geometry>
            <cylinder>
              <length>0.045</length>
              <radius>0.045</radius>
            </cylinder>
          </geometry>
          <max_contacts>10</max_contacts>
          <surface>
            <contact>
              <ode/>
            </contact>
            <bounce/>
            <friction>
              <torsional>
                <ode/>
              </torsional>
              <ode/>
            </friction>
          </surface>
        </collision>
        <visual name='front_left_wheel_link_visual'>
          <pose>0 0 0 0 -0 0</pose>
          <geometry>
            <mesh>
              <scale>1 1 1</scale>
              <uri>file:///home/agilex/agilex_ws/install/limo_description/share/limo_description/meshes/limo_wheel.dae</uri>
            </mesh>
          </geometry>
        </visual>
        <self_collide>0</self_collide>
        <enable_wind>0</enable_wind>
        <kinematic>0</kinematic>
      </link>
      <joint name='front_right_wheel' type='revolute'>
        <pose relative_to='base_footprint'>0.1 -0.065 0.05 3.14159 -0 0</pose>
        <parent>base_footprint</parent>
        <child>front_right_wheel_link</child>
        <axis>
          <xyz>0 -1 0</xyz>
          <limit>
            <lower>-1e+16</lower>
            <upper>1e+16</upper>
          </limit>
          <dynamics>
            <spring_reference>0</spring_reference>
            <spring_stiffness>0</spring_stiffness>
          </dynamics>
        </axis>
        <physics>
          <ode>
            <limit>
              <cfm>0</cfm>
              <erp>0.2</erp>
            </limit>
          </ode>
        </physics>
      </joint>
      <link name='front_right_wheel_link'>
        <pose relative_to='front_right_wheel'>0 0 0 0 -0 0</pose>
        <inertial>
          <pose>0 0 0 0 -0 0</pose>
          <mass>0.5</mass>
          <inertia>
            <ixx>0.01055</ixx>
            <ixy>0</ixy>
            <ixz>0</ixz>
            <iyy>0.00075</iyy>
            <iyz>0</iyz>
            <izz>0.01055</izz>
          </inertia>
        </inertial>
        <collision name='front_right_wheel_link_collision'>
          <pose>0 0.0225 0 1.57 -0 0</pose>
          <geometry>
            <cylinder>
              <length>0.045</length>
              <radius>0.045</radius>
            </cylinder>
          </geometry>
          <max_contacts>10</max_contacts>
          <surface>
            <contact>
              <ode/>
            </contact>
            <bounce/>
            <friction>
              <torsional>
                <ode/>
              </torsional>
              <ode/>
            </friction>
          </surface>
        </collision>
        <visual name='front_right_wheel_link_visual'>
          <pose>0 0 0 0 -0 0</pose>
          <geometry>
            <mesh>
              <scale>1 1 1</scale>
              <uri>file:///home/agilex/agilex_ws/install/limo_description/share/limo_description/meshes/limo_wheel.dae</uri>
            </mesh>
          </geometry>
        </visual>
        <self_collide>0</self_collide>
        <enable_wind>0</enable_wind>
        <kinematic>0</kinematic>
      </link>
      <joint name='rear_left_wheel' type='revolute'>
        <pose relative_to='base_footprint'>-0.1 0.065 0.05 0 -0 0</pose>
        <parent>base_footprint</parent>
        <child>rear_left_wheel_link</child>
        <axis>
          <xyz>0 1 0</xyz>
          <limit>
            <lower>-1e+16</lower>
            <upper>1e+16</upper>
          </limit>
          <dynamics>
            <spring_reference>0</spring_reference>
            <spring_stiffness>0</spring_stiffness>
          </dynamics>
        </axis>
        <physics>
          <ode>
            <limit>
              <cfm>0</cfm>
              <erp>0.2</erp>
            </limit>
          </ode>
        </physics>
      </joint>
      <link name='rear_left_wheel_link'>
        <pose relative_to='rear_left_wheel'>0 0 0 0 -0 0</pose>
        <inertial>
          <pose>0 0 0 0 -0 0</pose>
          <mass>0.5</mass>
          <inertia>
            <ixx>0.01055</ixx>
            <ixy>0</ixy>
            <ixz>0</ixz>
            <iyy>0.00075</iyy>
            <iyz>0</iyz>
            <izz>0.01055</izz>
          </inertia>
        </inertial>
        <collision name='rear_left_wheel_link_collision'>
          <pose>0 0.0225 0 1.57 -0 0</pose>
          <geometry>
            <cylinder>
              <length>0.045</length>
              <radius>0.045</radius>
            </cylinder>
          </geometry>
          <max_contacts>10</max_contacts>
          <surface>
            <contact>
              <ode/>
            </contact>
            <bounce/>
            <friction>
              <torsional>
                <ode/>
              </torsional>
              <ode/>
            </friction>
          </surface>
        </collision>
        <visual name='rear_left_wheel_link_visual'>
          <pose>0 0 0 0 -0 0</pose>
          <geometry>
            <mesh>
              <scale>1 1 1</scale>
              <uri>file:///home/agilex/agilex_ws/install/limo_description/share/limo_description/meshes/limo_wheel.dae</uri>
            </mesh>
          </geometry>
        </visual>
        <self_collide>0</self_collide>
        <enable_wind>0</enable_wind>
        <kinematic>0</kinematic>
      </link>
      <joint name='rear_right_wheel' type='revolute'>
        <pose relative_to='base_footprint'>-0.1 -0.065 0.05 3.14159 -0 0</pose>
        <parent>base_footprint</parent>
        <child>rear_right_wheel_link</child>
        <axis>
          <xyz>0 -1 0</xyz>
          <limit>
            <lower>-1e+16</lower>
            <upper>1e+16</upper>
          </limit>
          <dynamics>
            <spring_reference>0</spring_reference>
            <spring_stiffness>0</spring_stiffness>
          </dynamics>
        </axis>
        <physics>
          <ode>
            <limit>
              <cfm>0</cfm>
              <erp>0.2</erp>
            </limit>
          </ode>
        </physics>
      </joint>
      <link name='rear_right_wheel_link'>
        <pose relative_to='rear_right_wheel'>0 0 0 0 -0 0</pose>
        <inertial>
          <pose>0 0 0 0 -0 0</pose>
          <mass>0.5</mass>
          <inertia>
            <ixx>0.01055</ixx>
            <ixy>0</ixy>
            <ixz>0</ixz>
            <iyy>0.00075</iyy>
            <iyz>0</iyz>
            <izz>0.01055</izz>
          </inertia>
        </inertial>
        <collision name='rear_right_wheel_link_collision'>
          <pose>0 0.0225 0 1.57 -0 0</pose>
          <geometry>
            <cylinder>
              <length>0.045</length>
              <radius>0.045</radius>
            </cylinder>
          </geometry>
          <max_contacts>10</max_contacts>
          <surface>
            <contact>
              <ode/>
            </contact>
            <bounce/>
            <friction>
              <torsional>
                <ode/>
              </torsional>
              <ode/>
            </friction>
          </surface>
        </collision>
        <visual name='rear_right_wheel_link_visual'>
          <pose>0 0 0 0 -0 0</pose>
          <geometry>
            <mesh>
              <scale>1 1 1</scale>
              <uri>file:///home/agilex/agilex_ws/install/limo_description/share/limo_description/meshes/limo_wheel.dae</uri>
            </mesh>
          </geometry>
        </visual>
        <self_collide>0</self_collide>
        <enable_wind>0</enable_wind>
        <kinematic>0</kinematic>
      </link>
      <static>0</static>
      <plugin name='four_diff_controller' filename='libgazebo_ros_diff_drive.so'>
        <update_rate>50</update_rate>
        <num_wheel_pairs>2</num_wheel_pairs>
        <left_joint>front_left_wheel</left_joint>
        <right_joint>front_right_wheel</right_joint>
        <left_joint>rear_left_wheel</left_joint>
        <right_joint>rear_right_wheel</right_joint>
        <wheel_separation>0.172</wheel_separation>
        <wheel_diameter>0.09</wheel_diameter>
        <max_wheel_torque>20</max_wheel_torque>
        <max_wheel_acceleration>1.0</max_wheel_acceleration>
        <command_topic>cmd_vel</command_topic>
        <publish_odom>1</publish_odom>
        <publish_odom_tf>1</publish_odom_tf>
        <publish_wheel_tf>1</publish_wheel_tf>
        <odometry_topic>odom</odometry_topic>
        <odometry_frame>odom</odometry_frame>
        <robot_base_frame>base_footprint</robot_base_frame>
        <odometry_source>1</odometry_source>
        <ros>
          <remapping>odom:=/odometry</remapping>
        </ros>
      </plugin>
      <pose>0 0 0 0 -0 0</pose>
    </model>
    <model name='unit_sphere_0'>
      <pose>0.00152 1.20343 0.5 0 -0 0</pose>
      <link name='link'>
        <inertial>
          <mass>1</mass>
          <inertia>
            <ixx>0.1</ixx>
            <ixy>0</ixy>
            <ixz>0</ixz>
            <iyy>0.1</iyy>
            <iyz>0</iyz>
            <izz>0.1</izz>
          </inertia>
          <pose>0 0 0 0 -0 0</pose>
        </inertial>
        <collision name='collision'>
          <geometry>
            <sphere>
              <radius>0.5</radius>
            </sphere>
          </geometry>
          <max_contacts>10</max_contacts>
          <surface>
            <contact>
              <ode/>
            </contact>
            <bounce/>
            <friction>
              <torsional>
                <ode/>
              </torsional>
              <ode/>
            </friction>
          </surface>
        </collision>
        <visual name='visual'>
          <geometry>
            <sphere>
              <radius>0.5</radius>
            </sphere>
          </geometry>
          <material>
            <script>
              <name>Gazebo/Grey</name>
              <uri>file://media/materials/scripts/gazebo.material</uri>
            </script>
          </material>
        </visual>
        <self_collide>0</self_collide>
        <enable_wind>0</enable_wind>
        <kinematic>0</kinematic>
      </link>
    </model>
    <state world_name='default'>
      <sim_time>7074 983000000</sim_time>
      <real_time>5660 486834186</real_time>
      <wall_time>1720039912 365948293</wall_time>
      <iterations>5485000</iterations>
      <model name='ground_plane'>
        <pose>0 0 0 0 -0 0</pose>
        <scale>1 1 1</scale>
        <link name='link'>
          <pose>0 0 0 0 -0 0</pose>
          <velocity>0 0 0 0 -0 0</velocity>
          <acceleration>0 0 0 0 -0 0</acceleration>
          <wrench>0 0 0 0 -0 0</wrench>
        </link>
      </model>
      <model name='limo_description'>
        <pose>0.009444 -0.125071 -0.004991 4.4e-05 3.1e-05 2.3848</pose>
        <scale>1 1 1</scale>
        <link name='base_footprint'>
          <pose>0.009444 -0.125071 -0.004991 4.4e-05 3.1e-05 2.3848</pose>
          <velocity>0.000419 0.000354 -0.001449 0.009531 -0.006896 0.00201</velocity>
          <acceleration>-0.683501 -1.34681 -1.55745 -1.06756 0.96854 -3.00938</acceleration>
          <wrench>-1.61696 -3.18615 -3.68447 0 -0 0</wrench>
        </link>
        <link name='front_left_wheel_link'>
          <pose>-0.107889 -0.103666 0.045008 8.8e-05 1.05098 2.38487</pose>
          <velocity>1.7e-05 -0.000382 -0.00204 0.009469 -0.006837 0.002019</velocity>
          <acceleration>-0.086458 -0.200293 -1.99474 0.637849 0.321564 -2.94886</acceleration>
          <wrench>-0.043229 -0.100146 -0.99737 0 -0 0</wrench>
        </link>
        <link name='front_right_wheel_link'>
          <pose>-0.018632 -0.009152 0.045003 -0.000894 -1.52318 -0.755902</pose>
          <velocity>-0.000295 -0.000381 -0.000527 0.007574 -0.008275 0.001929</velocity>
          <acceleration>-0.251586 -0.402386 -0.508507 0.622458 0.426722 0.102888</acceleration>
          <wrench>-0.125793 -0.201193 -0.254254 0 -0 0</wrench>
        </link>
        <link name='rear_left_wheel_link'>
          <pose>0.037519 -0.240985 0.045015 3.14155 0.317484 -0.75681</pose>
          <velocity>0.000317 -0.000116 -0.002395 0.009482 -0.006847 0.002009</velocity>
          <acceleration>-0.058048 -0.151642 -2.64527 0.7024 0.263859 -2.94789</acceleration>
          <wrench>-0.029024 -0.075821 -1.32264 0 -0 0</wrench>
        </link>
        <link name='rear_right_wheel_link'>
          <pose>0.126777 -0.14647 0.045009 -3.14144 -1.29803 2.38465</pose>
          <velocity>0.00012 0.000122 -0.000844 0.009539 -0.006901 0.002008</velocity>
          <acceleration>-0.076229 -0.150812 -1.17615 0.591005 0.363202 -2.94799</acceleration>
          <wrench>-0.038115 -0.075406 -0.588075 0 -0 0</wrench>
        </link>
      </model>
      <model name='unit_sphere_0'>
        <pose>0.483842 1.43719 0.5 0 -0 0</pose>
        <scale>1 1 1</scale>
        <link name='link'>
          <pose>0.483842 1.43719 0.5 0 -0 0</pose>
          <velocity>0 0 0 0 -0 0</velocity>
          <acceleration>0 0 0 0 -0 0</acceleration>
          <wrench>0 0 0 0 -0 0</wrench>
        </link>
      </model>
      <light name='sun'>
        <pose>0 0 10 0 -0 0</pose>
      </light>
    </state>
    <gui fullscreen='0'>
      <camera name='user_camera'>
        <pose>-1.23919 -0.602971 27.9473 0 1.5418 -0.010248</pose>
        <view_controller>orbit</view_controller>
        <projection_type>perspective</projection_type>
      </camera>
    </gui>
  </world>
</sdf>
